<mujoco> 
   <!--add gravity?--> 
   <option gravity="0 0 -9"/>

    <worldbody>
        <!--try this   <light diffuse=”0.5 0.5 0.5” pos=”0 0 2” dir=”0 -1 0”/>      -->
        <light diffuse=".5 .5 .5" pos="0 0 3" dir="0 0 -1"/>
        
        <geom type="plane" size="10 10 0.1" rgba=".9 0 0 1"/>

        <body pos="0 0 1">
			<joint type="free"/>
			<geom type="box" size=".6 .3 .1" rgba="0 .9 0 1"/>
            
            <!-- back left leg -->
            <body pos="0.4 -0.3 -0.1" euler='90 0 0'>
			    <joint name="back_left_leg" type="hinge" axis="0 0 1"/>
			    <geom type="cylinder" size=".1 .1 " rgba="0 0.2 0.7 1"/>
		    </body>

            <!-- back right leg -->
            <body pos="0.4 0.3 -0.1" euler='90 0 0'>
			    <joint name="back_right_leg" type="hinge" axis="0 0 1"/>
			    <geom type="cylinder" size=".1 .1 " rgba="0 0.2 0.7 1"/>
		    </body>

            <!-- front left leg -->
            <body pos="-0.4 -0.3 -0.1" euler='90 0 0'>
			    <joint name="front_left_leg" type="hinge" axis="0 0 1"/>
			    <geom type="cylinder" size=".1 .1 " rgba="0 0.2 0.7 1"/>
		    </body>

            <!-- front right leg -->
            <body pos="-0.4  0.3 -0.1" euler='90 0 0'>
			    <joint name="front_right_leg" type="hinge" axis="0 0 1"/>
			    <geom type="cylinder" size=".1 .1 " rgba="0 0.2 0.7 1"/>
		    </body>
            

        
		</body>

    </worldbody>

    <actuator>
        <motor joint="back_left_leg" name="blg"/>
        <motor joint="back_right_leg" name="brg"/>
        <motor joint="front_left_leg" name="flg"/>
        <motor joint="front_right_leg" name="frg"/>
    </actuator>
</mujoco>